Workbook

Sheet README
B2: AI Guest Concierge — Financial Model
B3: Unit economics by property size · pricing · 24-month projection · sensitivity
B6: What this model answers
B7: 1. Cost to serve | C7: Fully loaded monthly COGS for four property archetypes (24, 50, 120, 250 rooms) and a group deal.
B8: 2. What to charge | C8: Pricing ladder with per-room anchoring, margin at each tier, and the price that minimises breakeven property count.
B9: 3. Does it scale | C9: 24-month projection: MRR, gross margin, opex, EBITDA, cash, breakeven month, peak funding need.
B10: 4. What breaks it | C10: Two-way sensitivity on conversation volume × WhatsApp share, plus LLM model tier and support-load effects.
B12: Headline findings
B13: Margins are healthy at every size | C13: Gross margin is 78–85% for all four archetypes and 85% for a group deal. The product is not margin-constrained — there is no AI-cost problem to solve.
B14: Support is the largest cost line | C14: 37–56% of COGS is human support. LLM spend is 5–15%. Margin is an operations problem, not an AI-cost problem.
B15: WhatsApp is smaller than feared | C15: Boutique and Independent never exceed the 1,000 free messages/month, so WhatsApp cost is $0. It only becomes material at 120+ rooms.
B16: Breakeven is an opex question | C16: ~8.7 properties at $3,800/mo of opex; ~28 at $12,000/mo. Team size, not growth rate, sets the target.
B17: The funded path needs real capital | C17: $150k is not enough for the contractor-led build at base-case sales velocity: ~$231k of peak funding and no breakeven inside 24 months. See Scenarios.
B18: The buyer's ROI, not our margin, is the constraint | C18: At Mexican labour rates the hotel's hard-value return is 0.39×–1.14× the price. At US resort rates it is 1.05×–3.09×. The same product is a hard sell to a small Mexican independent and an easy one to a resort. See Buyer ROI.
B19: So sell up-market and self-serve down-market | C19: Midscale, Resort and Group tiers carry defensible buyer ROI. Boutique and Independent must be sold on coverage and experience — and onboarded with near-zero human cost or they destroy margin.
B21: How to use it
B22: Edit yellow cells only | C22: Everything else is a formula. The Inputs sheet and the archetype parameters at the top of Unit Economics are the only places to type.
B23: Switch scenarios on Inputs | C23: Cell B7 selects Bootstrap / Funded / Group-led. The projection recalculates live.
B24: Scenarios sheet is a snapshot | C24: It holds computed values for all three so you can compare side by side without switching. Re-run after editing inputs.
B26: Method notes
B27: Volume driver | C27: Guest-nights = rooms × 30.4 × occupancy. Conversations = guest-nights × participation rate. Participation is the key unknown: 12–18% of guest-nights in year one.
B28: LLM cost | C28: Token-based, not a flat per-conversation guess: 45,000 input and 3,000 output tokens per conversation including classification, retrieval context and guardrail passes.
B29: Support load | C29: Hours per property per month × $22 loaded. This is the assumption most worth arguing about — it is the largest single cost.
B30: Churn | C30: 2.5% monthly (≈26% annualised). Typical for SMB SaaS; unproven for this category.
B31: Supersedes | C31: Replaces the rough per-property economics in 02-development-plan-workbook.xlsx → sheet 09, section D. That sheet is now build cost only.
B33: Caveats
B34: Pre-pilot estimates | C34: Every number here is a pre-pilot assumption. Participation, support hours and churn should be replaced with measured values after the first 8 weeks of pilot data.
B35: Currency | C35: USD throughout. Mexican VAT on software (16%) and local card-processing rates should be layered on before quoting.

Sheet Inputs
A1: Inputs — edit yellow cells only
A2: Archetype-specific parameters live at the top of the Unit Economics sheet, not here.
A4: A. Scenario selector
A5: Active scenario (1, 2 or 3) | B5: 2 | D5: 1 = Bootstrap (founders build, minimal opex) · 2 = Funded (contractor build, hired support) · 3 = Group-led (funded + faster pipeline)
A6: Active scenario name | B6: =CHOOSE(B5,"Bootstrap","Funded","Group-led") -> Funded
A8: B. Global operating assumptions
A9: Days per month | B9: 30.4
A10: Churn rate / month | B10: 0.025 | D10: Applied to the property and group base each month
A11: Support cost per hour (loaded) | B11: 22 | D11: Fully loaded: salary + overhead. Drives the largest COGS line.
A12: Payment processing fee (% of price) | B12: 0.036 | D12: Card + IVA on fees. Confirm with your PSP.
A14: C. AI cost
A15: Input tokens per conversation | B15: 45000 | D15: ~10 turns × (system + 4 retrieved chunks + history) + classification/guardrail calls
A16: Output tokens per conversation | B16: 3000
A17: Input price per 1M tokens (USD) | B17: 0.6 | D17: Mid-tier model. Cheap tier ≈ 0.15/0.60; premium ≈ 3.00/15.00.
A18: Output price per 1M tokens (USD) | B18: 2.4
A20: D. WhatsApp
A21: Service message rate (USD) | B21: 0.0085 | D21: Mexico, from 1 Oct 2026. Service messages are billable after the free allowance.
A22: Free messages per number / month | B22: 1000 | D22: Resets monthly, does not roll over
A24: E. Pricing (list, per month)
A25: Boutique (≤30 rooms) | B25: 199
A26: Independent (31–80 rooms) | B26: 299
A27: Midscale (81–150 rooms) | B27: 599
A28: Resort (151–400 rooms) | B28: 1099
A29: Group platform fee (per group / month) | B29: 1250 | D29: Charged on top of per-property fees at 85% of list
A30: Group per-property discount | B30: 0.15
A31: Blended group price (3 × Midscale) | B31: =3*B27*(1-B30)+B29 -> 2777.45
A32: Group COGS (calculated in Unit Economics) | B32: ='Unit Economics'!F23 -> 408.8816
A34: F. Scenario parameters
A35: Line | B35: 1 · Bootstrap | C35: 2 · Funded | D35: 3 · Group-led | E35: Unit / note
A36: Founder 1 monthly cost | B36: 1500 | C36: 2500 | D36: 2500 | E36: Founder draw, not market salary. Be honest about this line.
A37: Founder 2 monthly cost | B37: 1500 | C37: 0 | D37: 0 | E37: Second founder, technical. Zero in funded scenarios (contractor instead).
A38: Developer monthly cost | B38: 0 | C38: 3500 | D38: 3500 | E38: Contractor at ~$550/day × 16 days
A39: Second developer from month | B39: 99 | C39: 7 | D39: 7 | E39: 99 = never
A40: Second developer monthly cost | B40: 0 | C40: 3500 | D40: 3500
A41: Support / content ops from month | B41: 99 | C41: 4 | D41: 4 | E41: 99 = never (founders absorb)
A42: Support / content ops monthly cost | B42: 0 | C42: 1300 | D42: 1300
A43: Tools, hosting, software | B43: 400 | C43: 400 | D43: 400 | E43: Fixed platform cost, not per-property
A44: Marketing & sales | B44: 400 | C44: 800 | D44: 1200
A45: Pipeline multiplier | B45: 0.7 | C45: 1 | D45: 1.4 | E45: Applied to the base quarterly pipeline below
A46: Group deals: quarter of first close | B46: 0 | C46: 6 | D46: 3 | E46: 0 = no group deals in this scenario
...

Sheet Unit Economics
A1: Unit economics by property size
A2: Parameters in rows 5–10 are inputs (yellow). Everything below is calculated.
A4: Metric | B4: Boutique | C4: Independent | D4: Midscale | E4: Resort | F4: Group (3×Mid)
A5: Rooms | B5: 24 | C5: 50 | D5: 120 | E5: 250 | F5: 360 | G5: Group column = 3 × Midscale properties
A6: Occupancy | B6: 0.72 | C6: 0.68 | D6: 0.7 | E6: 0.75 | F6: 0.7
A7: Participation rate | B7: 0.12 | C7: 0.15 | D7: 0.17 | E7: 0.18 | F7: 0.15 | G7: Share of guest-nights that produce a conversation. Biggest unknown in the model.
A8: Replies per conversation | B8: 9 | C8: 10 | D8: 11 | E8: 12 | F8: 11 | G8: Bot + staff messages
A9: WhatsApp share of conversations | B9: 0.35 | C9: 0.45 | D9: 0.55 | E9: 0.6 | F9: 0.55 | G9: Rest is web chat (near-zero marginal cost)
A10: Support hours / month | B10: 1 | C10: 1.5 | D10: 2.5 | E10: 4 | F10: 4.5 | G10: Group gets 40% support synergy vs 3 × 2.5
A11: Infra / month (allocation) | B11: 8 | C11: 10 | D11: 15 | E11: 20 | F11: 120 | G11: Hosting, storage, observability + governance
A12: List price / month | B12: =Inputs!$B$25 -> 199 | C12: =Inputs!$B$26 -> 299 | D12: =Inputs!$B$27 -> 599 | E12: =Inputs!$B$28 -> 1099 | F12: =Inputs!$B$31 -> 2777.45 | G12: Group = 3 × Mid at 85% + $1,250 platform fee
A14: Calculated economics
A15: Guest-nights / month | B15: =B5*Inputs!$B$9*B6 -> 525.312 | C15: =C5*Inputs!$B$9*C6 -> 1033.6 | D15: =D5*Inputs!$B$9*D6 -> 2553.6 | E15: =E5*Inputs!$B$9*E6 -> 5700 | F15: =F5*Inputs!$B$9*F6 -> 7660.8 | G15: Rooms × days × occupancy
A16: Conversations / month | B16: =B15*B7 -> 63.03744 | C16: =C15*C7 -> 155.04 | D16: =D15*D7 -> 434.112 | E16: =E15*E7 -> 1026 | F16: =F15*F7 -> 1149.12 | G16: Guest-nights × participation
A17: LLM cost | B17: =B16*(Inputs!$B$15/1000000*Inputs!$B$17+Inputs!$B$16/1000000*Inputs!$B$18) -> 2.1558804 | C17: =C16*(Inputs!$B$15/1000000*Inputs!$B$17+Inputs!$B$16/1000000*Inputs!$B$18) -> 5.302368 | D17: =D16*(Inputs!$B$15/1000000*Inputs!$B$17+Inputs!$B$16/1000000*Inputs!$B$18) -> 14.84663 | E17: =E16*(Inputs!$B$15/1000000*Inputs!$B$17+Inputs!$B$16/1000000*Inputs!$B$18) -> 35.0892 | F17: =F16*(Inputs!$B$15/1000000*Inputs!$B$17+Inputs!$B$16/1000000*Inputs!$B$18) -> 39.299904 | G17: Token-based
A18: WhatsApp messages sent | B18: =B16*B9*B8 -> 198.56794 | C18: =C16*C9*C8 -> 697.68 | D18: =D16*D9*D8 -> 2626.3776 | E18: =E16*E9*E8 -> 7387.2 | F18: =F16*F9*F8 -> 6952.176
A19: WhatsApp cost | B19: =MAX(0,B18-Inputs!$B$22)*Inputs!$B$21 -> 0 | C19: =MAX(0,C18-Inputs!$B$22)*Inputs!$B$21 -> 0 | D19: =MAX(0,D18-Inputs!$B$22)*Inputs!$B$21 -> 13.82421 | E19: =MAX(0,E18-Inputs!$B$22)*Inputs!$B$21 -> 54.2912 | F19: =MAX(0,F18-Inputs!$B$22)*Inputs!$B$21 -> 50.593496 | G19: After the 1,000 free messages/number
A20: Support cost | B20: =B10*Inputs!$B$11 -> 22 | C20: =C10*Inputs!$B$11 -> 33 | D20: =D10*Inputs!$B$11 -> 55 | E20: =E10*Inputs!$B$11 -> 88 | F20: =F10*Inputs!$B$11 -> 99 | G20: Largest COGS line
A21: Infrastructure | B21: =B11 -> 8 | C21: =C11 -> 10 | D21: =D11 -> 15 | E21: =E11 -> 20 | F21: =F11 -> 120
A22: Payment processing | B22: =B12*Inputs!$B$12 -> 7.164 | C22: =C12*Inputs!$B$12 -> 10.764 | D22: =D12*Inputs!$B$12 -> 21.564 | E22: =E12*Inputs!$B$12 -> 39.564 | F22: =F12*Inputs!$B$12 -> 99.9882
A23: Total COGS | B23: =B17+B19+B20+B21+B22 -> 39.31988 | C23: =C17+C19+C20+C21+C22 -> 59.066368 | D23: =D17+D19+D20+D21+D22 -> 120.23484 | E23: =E17+E19+E20+E21+E22 -> 236.9444 | F23: =F17+F19+F20+F21+F22 -> 408.8816
A24: Gross profit / month | B24: =B12-B23 -> 159.68012 | C24: =C12-C23 -> 239.93363 | D24: =D12-D23 -> 478.76516 | E24: =E12-E23 -> 862.0556 | F24: =F12-F23 -> 2368.5684
A25: Gross margin | B25: =B24/B12 -> 0.80241266 | C25: =C24/C12 -> 0.80245362 | D25: =D24/D12 -> 0.79927406 | E25: =E24/E12 -> 0.7844 | F25: =F24/F12 -> 0.85278525
A26: Price per room / month | B26: =B12/B5 -> 8.2916667 | C26: =C12/C5 -> 5.98 | D26: =D12/D5 -> 4.9916667 | E26: =E12/E5 -> 4.396 | F26: =F12/F5 -> 7.7151389 | G26: Anchors the sales conversation
A27: Cost per conversation | B27: =B23/B16 -> 0.6237544 | C27: =C23/C16 -> 0.38097503 | D27: =D23/D16 -> 0.27696733 | E27: =E23/E16 -> 0.23093996 | F27: =F23/F16 -> 0.3558215 | G27: Falls with size — fixed support spread over more volume
A28: Support share of COGS | B28: =B20/B23 -> 0.5595134 | C28: =C20/C23 -> 0.55869357 | D28: =D20/D23 -> 0.45743813 | E28: =E20/E23 -> 0.37139515 | F28: =F20/F23 -> 0.24212388 | G28: The line to attack
A29: LLM share of COGS | B29: =B17/B23 -> 0.054829273 | C29: =C17/C23 -> 0.089769664 | D29: =D17/D23 -> 0.12348027 | E29: =E17/E23 -> 0.14809044 | F29: =F17/F23 -> 0.096115609
A30: WhatsApp share of COGS | B30: =B19/B23 -> 0 | C30: =C19/C23 -> 0 | D30: =D19/D23 -> 0.11497674 | E30: =E19/E23 -> 0.22913055 | F30: =F19/F23 -> 0.1237363
A31: Annual gross profit per property | B31: =B24*12 -> 1916.1614 | C31: =C24*12 -> 2879.2036 | D31: =D24*12 -> 5745.1819 | E31: =E24*12 -> 10344.667 | F31: =F24*12 -> 28422.821
A32: Properties needed per $10k of monthly opex | B32: =10000/B24 -> 62.625204 | C32: =10000/C24 -> 41.678192 | D32: =10000/D24 -> 20.887067 | E32: =10000/E24 -> 11.60018 | F32: =10000/F24 -> 4.2219596 | G32: Lower is better

Sheet Pricing
A1: Pricing ladder and price sensitivity
A2: Prices are set on Inputs. This sheet tests whether they are right.
A4: A. Ladder as designed
A5: Tier | B5: Price / mo | C5: Price / room | D5: COGS | E5: Gross profit | F5: GM % | G5: Included conversations | H5: Positioning
A6: Boutique | B6: ='Unit Economics'!B12 -> 199 | C6: ='Unit Economics'!B26 -> 8.2916667 | D6: ='Unit Economics'!B23 -> 39.31988 | E6: ='Unit Economics'!B24 -> 159.68012 | F6: ='Unit Economics'!B25 -> 0.80241266 | G6: ='Unit Economics'!B16 -> 63.03744 | H6: Entry; replaces the FAQ page and the phone that nobody answers
A7: Independent | B7: ='Unit Economics'!C12 -> 299 | C7: ='Unit Economics'!C26 -> 5.98 | D7: ='Unit Economics'!C23 -> 59.066368 | E7: ='Unit Economics'!C24 -> 239.93363 | F7: ='Unit Economics'!C25 -> 0.80245362 | G7: ='Unit Economics'!C16 -> 155.04 | H7: Core offer; priced roughly at the value of the front-desk interruptions it removes
A8: Midscale | B8: ='Unit Economics'!D12 -> 599 | C8: ='Unit Economics'!D26 -> 4.9916667 | D8: ='Unit Economics'!D23 -> 120.23484 | E8: ='Unit Economics'!D24 -> 478.76516 | F8: ='Unit Economics'!D25 -> 0.79927406 | G8: ='Unit Economics'!D16 -> 434.112 | H8: Multi-outlet; WhatsApp and spa/F&B routing matter here
A9: Resort | B9: ='Unit Economics'!E12 -> 1099 | C9: ='Unit Economics'!E26 -> 4.396 | D9: ='Unit Economics'!E23 -> 236.9444 | E9: ='Unit Economics'!E24 -> 862.0556 | F9: ='Unit Economics'!E25 -> 0.7844 | G9: ='Unit Economics'!E16 -> 1026 | H9: Highest value per property; group reporting and escalation SLAs
A10: Group (3 properties) | B10: ='Unit Economics'!F12 -> 2777.45 | C10: ='Unit Economics'!F12/300 -> 9.2581667 | D10: ='Unit Economics'!F23 -> 408.8816 | E10: ='Unit Economics'!F24 -> 2368.5684 | F10: ='Unit Economics'!F25 -> 0.85278525 | G10: =SUM('Unit Economics'!F16) -> 1149.12 | H10: Governance, brand inheritance, group reporting, SSO
A14: B. Price sensitivity — Independent tier
A15: At a steady opex of $12,000/month, how many Independents cover the burn?
A16: Price / mo | B16: Gross profit | C16: GM % | D16: Properties to break even | E16: Extra vs. $299 | F16: Verdict
A17: 199 | B17: =A17-('Unit Economics'!C23-'Unit Economics'!C12*Inputs!$B$12)-A17*Inputs!$B$12 -> 143.53363 | C17: =B17/A17 -> 0.72127453 | D17: =12000/B17 -> 83.604099 | E17: =D17-12000/('Unit Economics'!C24) -> 33.590269 | F17: Floor. Only viable with self-serve onboarding.
A18: 249 | B18: =A18-('Unit Economics'!C23-'Unit Economics'!C12*Inputs!$B$12)-A18*Inputs!$B$12 -> 191.73363 | C18: =B18/A18 -> 0.77001459 | D18: =12000/B18 -> 62.586829 | E18: =D18-12000/('Unit Economics'!C24) -> 12.572998 | F18: Aggressive; use for annual prepay, not standard
A19: 299 | B19: =A19-('Unit Economics'!C23-'Unit Economics'!C12*Inputs!$B$12)-A19*Inputs!$B$12 -> 239.93363 | C19: =B19/A19 -> 0.80245362 | D19: =12000/B19 -> 50.01383 | E19: =D19-12000/('Unit Economics'!C24) -> 0 | F19: Recommended launch price for Independent
A20: 349 | B20: =A20-('Unit Economics'!C23-'Unit Economics'!C12*Inputs!$B$12)-A20*Inputs!$B$12 -> 288.13363 | C20: =B20/A20 -> 0.8255978 | D20: =12000/B20 -> 41.647342 | E20: =D20-12000/('Unit Economics'!C24) -> -8.3664882 | F20: Post-pilot price once containment is proven
A21: 449 | B21: =A21-('Unit Economics'!C23-'Unit Economics'!C12*Inputs!$B$12)-A21*Inputs!$B$12 -> 384.53363 | C21: =B21/A21 -> 0.85642234 | D21: =12000/B21 -> 31.206633 | E21: =D21-12000/('Unit Economics'!C24) -> -18.807197 | F21: Needs a stronger ROI story than labour
A22: 599 | B22: =A22-('Unit Economics'!C23-'Unit Economics'!C12*Inputs!$B$12)-A22*Inputs!$B$12 -> 529.13363 | C22: =B22/A22 -> 0.88336166 | D22: =12000/B22 -> 22.678581 | E22: =D22-12000/('Unit Economics'!C24) -> -27.335249 | F22: Midscale territory — do not sell Independents here
A23: 749 | B23: =A23-('Unit Economics'!C23-'Unit Economics'!C12*Inputs!$B$12)-A23*Inputs!$B$12 -> 673.73363 | C23: =B23/A23 -> 0.89951086 | D23: =12000/B23 -> 17.811193 | E23: =D23-12000/('Unit Economics'!C24) -> -32.202637 | F23: Off-ladder
A25: Read: price has more leverage on breakeven than any cost line, because support cost is fixed per property and price is pure contribution.
A27: C. What to do with this
A28: 1. Launch at $299 / $599 for Independent and Midscale. $349 is the post-pilot price, once containment is proven.
A29: 2. Offer 2 months free on annual prepay rather than a lower monthly price. Cash today, same ARR, no precedent for discounting.
A30: 3. Quote per room per month ($5.98 for a 50-room hotel). It anchors against a hire, not against other software.
A31: 4. Revisit after 90 days of pilot data. If containment is above 55%, move the Independent price to $349 for new logos and grandfather the pilot.
A32: 5. Group: $1,250 platform fee + 85% of list per property. The platform fee is what pays for governance work you will otherwise do for free.
A34: D. Acquisition economics
A35: Customer acquisition cost (blended) | B35: 1750 | C35: Founder-led sales at trade events is cheaper; paid acquisition is dearer. Replace with actuals after 20 deals.
A36: Expected customer life (months) | B36: =1/Inputs!$B$10 -> 40 | C36: 1 ÷ monthly churn from Inputs
A38: Tier | B38: Gross profit / mo | C38: CAC payback (months) | D38: LTV (months × GP) | E38: LTV ÷ CAC
A39: Boutique | B39: ='Unit Economics'!B24 -> 159.68012 | C39: =$B$35/B39 -> 10.959411 | D39: =B39*$B$36 -> 6387.2048 | E39: =D39/$B$35 -> 3.6498313
A40: Independent | B40: ='Unit Economics'!C24 -> 239.93363 | C40: =$B$35/B40 -> 7.2936836 | D40: =B40*$B$36 -> 9597.3453 | E40: =D40/$B$35 -> 5.4841973
A41: Midscale | B41: ='Unit Economics'!D24 -> 478.76516 | C41: =$B$35/B41 -> 3.6552367 | D41: =B41*$B$36 -> 19150.606 | E41: =D41/$B$35 -> 10.943204
A42: Resort | B42: ='Unit Economics'!E24 -> 862.0556 | C42: =$B$35/B42 -> 2.0300315 | D42: =B42*$B$36 -> 34482.224 | E42: =D42/$B$35 -> 19.704128
A43: Boutique payback above 10 months is too long for a self-serve tier. Another argument for keeping its acquisition cost near zero and treating it as a reference logo, not a profit centre.

Sheet Projection
A1: 24-month projection — driven by the scenario selector on Inputs
A2: =CONCATENATE("Active scenario: ",Inputs!$B$6) -> Active scenario: Funded
A4: Line | C4: M1 | D4: M2 | E4: M3 | F4: M4 | G4: M5 | H4: M6 | I4: M7 | J4: M8 | K4: M9 | L4: M10 | M4: M11 | N4: M12 | O4: M13 | P4: M14 | Q4: M15 | R4: M16 | S4: M17 | T4: M18 | U4: M19 | V4: M20 | W4: M21 | X4: M22 | Y4: M23 | Z4: M24
A5: QUARTER | C5: =INT((1-1)/3)+1 -> 1 | D5: =INT((2-1)/3)+1 -> 1 | E5: =INT((3-1)/3)+1 -> 1 | F5: =INT((4-1)/3)+1 -> 2 | G5: =INT((5-1)/3)+1 -> 2 | H5: =INT((6-1)/3)+1 -> 2 | I5: =INT((7-1)/3)+1 -> 3 | J5: =INT((8-1)/3)+1 -> 3 | K5: =INT((9-1)/3)+1 -> 3 | L5: =INT((10-1)/3)+1 -> 4 | M5: =INT((11-1)/3)+1 -> 4 | N5: =INT((12-1)/3)+1 -> 4 | O5: =INT((13-1)/3)+1 -> 5 | P5: =INT((14-1)/3)+1 -> 5 | Q5: =INT((15-1)/3)+1 -> 5 | R5: =INT((16-1)/3)+1 -> 6 | S5: =INT((17-1)/3)+1 -> 6 | T5: =INT((18-1)/3)+1 -> 6 | U5: =INT((19-1)/3)+1 -> 7 | V5: =INT((20-1)/3)+1 -> 7 | W5: =INT((21-1)/3)+1 -> 7 | X5: =INT((22-1)/3)+1 -> 8 | Y5: =INT((23-1)/3)+1 -> 8 | Z5: =INT((24-1)/3)+1 -> 8
A6: Pipeline
A7: Boutique adds | C7: =INDEX(Inputs!$B$54:$I$54,C$5)*Inputs!$B$70/3 -> 0 | D7: =INDEX(Inputs!$B$54:$I$54,D$5)*Inputs!$B$70/3 -> 0 | E7: =INDEX(Inputs!$B$54:$I$54,E$5)*Inputs!$B$70/3 -> 0 | F7: =INDEX(Inputs!$B$54:$I$54,F$5)*Inputs!$B$70/3 -> 0.33333333 | G7: =INDEX(Inputs!$B$54:$I$54,G$5)*Inputs!$B$70/3 -> 0.33333333 | H7: =INDEX(Inputs!$B$54:$I$54,H$5)*Inputs!$B$70/3 -> 0.33333333 | I7: =INDEX(Inputs!$B$54:$I$54,I$5)*Inputs!$B$70/3 -> 0.33333333 | J7: =INDEX(Inputs!$B$54:$I$54,J$5)*Inputs!$B$70/3 -> 0.33333333 | ... Z7: =INDEX(Inputs!$B$54:$I$54,Z$5)*Inputs!$B$70/3 -> 0.33333333
A8: Independent adds | C8: =INDEX(Inputs!$B$55:$I$55,C$5)*Inputs!$B$70/3 -> 0.33333333 | D8: =INDEX(Inputs!$B$55:$I$55,D$5)*Inputs!$B$70/3 -> 0.33333333 | E8: =INDEX(Inputs!$B$55:$I$55,E$5)*Inputs!$B$70/3 -> 0.33333333 | F8: =INDEX(Inputs!$B$55:$I$55,F$5)*Inputs!$B$70/3 -> 0.66666667 | G8: =INDEX(Inputs!$B$55:$I$55,G$5)*Inputs!$B$70/3 -> 0.66666667 | H8: =INDEX(Inputs!$B$55:$I$55,H$5)*Inputs!$B$70/3 -> 0.66666667 | I8: =INDEX(Inputs!$B$55:$I$55,I$5)*Inputs!$B$70/3 -> 0.66666667 | J8: =INDEX(Inputs!$B$55:$I$55,J$5)*Inputs!$B$70/3 -> 0.66666667 | ... Z8: =INDEX(Inputs!$B$55:$I$55,Z$5)*Inputs!$B$70/3 -> 0.66666667
A9: Midscale adds | C9: =INDEX(Inputs!$B$56:$I$56,C$5)*Inputs!$B$70/3 -> 0 | D9: =INDEX(Inputs!$B$56:$I$56,D$5)*Inputs!$B$70/3 -> 0 | E9: =INDEX(Inputs!$B$56:$I$56,E$5)*Inputs!$B$70/3 -> 0 | F9: =INDEX(Inputs!$B$56:$I$56,F$5)*Inputs!$B$70/3 -> 0 | G9: =INDEX(Inputs!$B$56:$I$56,G$5)*Inputs!$B$70/3 -> 0 | H9: =INDEX(Inputs!$B$56:$I$56,H$5)*Inputs!$B$70/3 -> 0 | I9: =INDEX(Inputs!$B$56:$I$56,I$5)*Inputs!$B$70/3 -> 0 | J9: =INDEX(Inputs!$B$56:$I$56,J$5)*Inputs!$B$70/3 -> 0 | ... Z9: =INDEX(Inputs!$B$56:$I$56,Z$5)*Inputs!$B$70/3 -> 0.33333333
A10: Resort adds | C10: =INDEX(Inputs!$B$57:$I$57,C$5)*Inputs!$B$70/3 -> 0 | D10: =INDEX(Inputs!$B$57:$I$57,D$5)*Inputs!$B$70/3 -> 0 | E10: =INDEX(Inputs!$B$57:$I$57,E$5)*Inputs!$B$70/3 -> 0 | F10: =INDEX(Inputs!$B$57:$I$57,F$5)*Inputs!$B$70/3 -> 0 | G10: =INDEX(Inputs!$B$57:$I$57,G$5)*Inputs!$B$70/3 -> 0 | H10: =INDEX(Inputs!$B$57:$I$57,H$5)*Inputs!$B$70/3 -> 0 | I10: =INDEX(Inputs!$B$57:$I$57,I$5)*Inputs!$B$70/3 -> 0 | J10: =INDEX(Inputs!$B$57:$I$57,J$5)*Inputs!$B$70/3 -> 0 | ... Z10: =INDEX(Inputs!$B$57:$I$57,Z$5)*Inputs!$B$70/3 -> 0.33333333
A11: Group deals added | C11: =IF(OR($C$5=Inputs!$B$71,$C$5=Inputs!$B$72),1,0)/3 -> 0 | D11: =IF(OR($D$5=Inputs!$B$71,$D$5=Inputs!$B$72),1,0)/3 -> 0 | E11: =IF(OR($E$5=Inputs!$B$71,$E$5=Inputs!$B$72),1,0)/3 -> 0 | F11: =IF(OR($F$5=Inputs!$B$71,$F$5=Inputs!$B$72),1,0)/3 -> 0 | G11: =IF(OR($G$5=Inputs!$B$71,$G$5=Inputs!$B$72),1,0)/3 -> 0 | H11: =IF(OR($H$5=Inputs!$B$71,$H$5=Inputs!$B$72),1,0)/3 -> 0 | I11: =IF(OR($I$5=Inputs!$B$71,$I$5=Inputs!$B$72),1,0)/3 -> 0 | J11: =IF(OR($J$5=Inputs!$B$71,$J$5=Inputs!$B$72),1,0)/3 -> 0 | K11: =IF(OR($K$5=Inputs!$B$71,$K$5=Inputs!$B$72),1,0)/3 -> 0 | L11: =IF(OR($L$5=Inputs!$B$71,$L$5=Inputs!$B$72),1,0)/3 -> 0 | M11: =IF(OR($M$5=Inputs!$B$71,$M$5=Inputs!$B$72),1,0)/3 -> 0 | N11: =IF(OR($N$5=Inputs!$B$71,$N$5=Inputs!$B$72),1,0)/3 -> 0 | O11: =IF(OR($O$5=Inputs!$B$71,$O$5=Inputs!$B$72),1,0)/3 -> 0 | P11: =IF(OR($P$5=Inputs!$B$71,$P$5=Inputs!$B$72),1,0)/3 -> 0 | Q11: =IF(OR($Q$5=Inputs!$B$71,$Q$5=Inputs!$B$72),1,0)/3 -> 0 | R11: =IF(OR($R$5=Inputs!$B$71,$R$5=Inputs!$B$72),1,0)/3 -> 0.33333333 | S11: =IF(OR($S$5=Inputs!$B$71,$S$5=Inputs!$B$72),1,0)/3 -> 0.33333333 | T11: =IF(OR($T$5=Inputs!$B$71,$T$5=Inputs!$B$72),1,0)/3 -> 0.33333333 | U11: =IF(OR($U$5=Inputs!$B$71,$U$5=Inputs!$B$72),1,0)/3 -> 0 | V11: =IF(OR($V$5=Inputs!$B$71,$V$5=Inputs!$B$72),1,0)/3 -> 0 | W11: =IF(OR($W$5=Inputs!$B$71,$W$5=Inputs!$B$72),1,0)/3 -> 0 | X11: =IF(OR($X$5=Inputs!$B$71,$X$5=Inputs!$B$72),1,0)/3 -> 0 | Y11: =IF(OR($Y$5=Inputs!$B$71,$Y$5=Inputs!$B$72),1,0)/3 -> 0 | Z11: =IF(OR($Z$5=Inputs!$B$71,$Z$5=Inputs!$B$72),1,0)/3 -> 0
A12: Installed base
A13: Boutique base | C13: =C7 -> 0 | D13: =C13*(1-Inputs!$B$10)+D7 -> 0 | E13: =D13*(1-Inputs!$B$10)+E7 -> 0 | F13: =E13*(1-Inputs!$B$10)+F7 -> 0.33333333 | G13: =F13*(1-Inputs!$B$10)+G7 -> 0.65833333 | H13: =G13*(1-Inputs!$B$10)+H7 -> 0.97520833 | I13: =H13*(1-Inputs!$B$10)+I7 -> 1.2841615 | J13: =I13*(1-Inputs!$B$10)+J7 -> 1.5853908 | K13: =J13*(1-Inputs!$B$10)+K7 -> 1.8790893 | ... Z13: =Y13*(1-Inputs!$B$10)+Z7 -> 5.4983935
A14: Independent base | C14: =C8 -> 0.33333333 | D14: =C14*(1-Inputs!$B$10)+D8 -> 0.65833333 | E14: =D14*(1-Inputs!$B$10)+E8 -> 0.97520833 | F14: =E14*(1-Inputs!$B$10)+F8 -> 1.6174948 | G14: =F14*(1-Inputs!$B$10)+G8 -> 2.2437241 | H14: =G14*(1-Inputs!$B$10)+H8 -> 2.8542977 | I14: =H14*(1-Inputs!$B$10)+I8 -> 3.4496069 | J14: =I14*(1-Inputs!$B$10)+J8 -> 4.0300334 | K14: =J14*(1-Inputs!$B$10)+K8 -> 4.5959492 | ... Z14: =Y14*(1-Inputs!$B$10)+Z8 -> 12.289542
A15: Midscale base | C15: =C9 -> 0 | D15: =C15*(1-Inputs!$B$10)+D9 -> 0 | E15: =D15*(1-Inputs!$B$10)+E9 -> 0 | F15: =E15*(1-Inputs!$B$10)+F9 -> 0 | G15: =F15*(1-Inputs!$B$10)+G9 -> 0 | H15: =G15*(1-Inputs!$B$10)+H9 -> 0 | I15: =H15*(1-Inputs!$B$10)+I9 -> 0 | J15: =I15*(1-Inputs!$B$10)+J9 -> 0 | K15: =J15*(1-Inputs!$B$10)+K9 -> 0 | ... Z15: =Y15*(1-Inputs!$B$10)+Z9 -> 3.4933554
A16: Resort base | C16: =C10 -> 0 | D16: =C16*(1-Inputs!$B$10)+D10 -> 0 | E16: =D16*(1-Inputs!$B$10)+E10 -> 0 | F16: =E16*(1-Inputs!$B$10)+F10 -> 0 | G16: =F16*(1-Inputs!$B$10)+G10 -> 0 | H16: =G16*(1-Inputs!$B$10)+H10 -> 0 | I16: =H16*(1-Inputs!$B$10)+I10 -> 0 | J16: =I16*(1-Inputs!$B$10)+J10 -> 0 | K16: =J16*(1-Inputs!$B$10)+K10 -> 0 | ... Z16: =Y16*(1-Inputs!$B$10)+Z10 -> 0.97520833
A17: Group base | C17: =C11 -> 0 | D17: =C17*(1-Inputs!$B$10)+D11 -> 0 | E17: =D17*(1-Inputs!$B$10)+E11 -> 0 | F17: =E17*(1-Inputs!$B$10)+F11 -> 0 | G17: =F17*(1-Inputs!$B$10)+G11 -> 0 | H17: =G17*(1-Inputs!$B$10)+H11 -> 0 | I17: =H17*(1-Inputs!$B$10)+I11 -> 0 | J17: =I17*(1-Inputs!$B$10)+J11 -> 0 | K17: =J17*(1-Inputs!$B$10)+K11 -> 0 | ... Z17: =Y17*(1-Inputs!$B$10)+Z11 -> 0.83777057
A18: Total properties | C18: =SUM(C13:C16) -> 0.33333333 | D18: =SUM(D13:D16) -> 0.65833333 | E18: =SUM(E13:E16) -> 0.97520833 | F18: =SUM(F13:F16) -> 1.9508281 | G18: =SUM(G13:G16) -> 2.9020574 | H18: =SUM(H13:H16) -> 3.829506 | I18: =SUM(I13:I16) -> 4.7337683 | J18: =SUM(J13:J16) -> 5.6154241 | ... Z18: =SUM(Z13:Z16) -> 22.256499
A19: Revenue and gross profit
A20: Boutique MRR | C20: =C13*'Unit Economics'!B12 -> 0 | D20: =D13*'Unit Economics'!B12 -> 0 | E20: =E13*'Unit Economics'!B12 -> 0 | F20: =F13*'Unit Economics'!B12 -> 66.333333 | G20: =G13*'Unit Economics'!B12 -> 131.00833 | H20: =H13*'Unit Economics'!B12 -> 194.06646 | I20: =I13*'Unit Economics'!B12 -> 255.54813 | J20: =J13*'Unit Economics'!B12 -> 315.49276 | K20: =K13*'Unit Economics'!B12 -> 373.93877 | L20: =L13*'Unit Economics'!B12 -> 430.92364 | M20: =M13*'Unit Economics'!B12 -> 486.48388 | N20: =N13*'Unit Economics'!B12 -> 540.65512 | O20: =O13*'Unit Economics'!B12 -> 593.47207 | P20: =P13*'Unit Economics'!B12 -> 644.9686 | Q20: =Q13*'Unit Economics'!B12 -> 695.17772 | R20: =R13*'Unit Economics'!B12 -> 744.13161 | S20: =S13*'Unit Economics'!B12 -> 791.86166 | T20: =T13*'Unit Economics'!B12 -> 838.39845 | U20: =U13*'Unit Economics'!B12 -> 883.77182 | V20: =V13*'Unit Economics'!B12 -> 928.01086 | W20: =W13*'Unit Economics'!B12 -> 971.14392 | X20: =X13*'Unit Economics'!B12 -> 1013.1987 | Y20: =Y13*'Unit Economics'!B12 -> 1054.202 | Z20: =Z13*'Unit Economics'!B12 -> 1094.1803
A21: Independent MRR | C21: =C14*'Unit Economics'!C12 -> 99.666667 | D21: =D14*'Unit Economics'!C12 -> 196.84167 | E21: =E14*'Unit Economics'!C12 -> 291.58729 | F21: =F14*'Unit Economics'!C12 -> 483.63094 | G21: =G14*'Unit Economics'!C12 -> 670.8735 | H21: =H14*'Unit Economics'!C12 -> 853.435 | I21: =I14*'Unit Economics'!C12 -> 1031.4325 | J21: =J14*'Unit Economics'!C12 -> 1204.98 | K21: =K14*'Unit Economics'!C12 -> 1374.1888 | L21: =L14*'Unit Economics'!C12 -> 1638.8341 | M21: =M14*'Unit Economics'!C12 -> 1896.8632 | N21: =N14*'Unit Economics'!C12 -> 2148.4417 | O21: =O14*'Unit Economics'!C12 -> 2294.064 | P21: =P14*'Unit Economics'!C12 -> 2436.0457 | Q21: =Q14*'Unit Economics'!C12 -> 2574.4779 | R21: =R14*'Unit Economics'!C12 -> 2709.4493 | S21: =S14*'Unit Economics'!C12 -> 2841.0464 | T21: =T14*'Unit Economics'!C12 -> 2969.3535 | U21: =U14*'Unit Economics'!C12 -> 3094.453 | V21: =V14*'Unit Economics'!C12 -> 3216.425 | W21: =W14*'Unit Economics'!C12 -> 3335.3477 | X21: =X14*'Unit Economics'!C12 -> 3451.2974 | Y21: =Y14*'Unit Economics'!C12 -> 3564.3483 | Z21: =Z14*'Unit Economics'!C12 -> 3674.5729
A22: Midscale MRR | C22: =C15*'Unit Economics'!D12 -> 0 | D22: =D15*'Unit Economics'!D12 -> 0 | E22: =E15*'Unit Economics'!D12 -> 0 | F22: =F15*'Unit Economics'!D12 -> 0 | G22: =G15*'Unit Economics'!D12 -> 0 | H22: =H15*'Unit Economics'!D12 -> 0 | I22: =I15*'Unit Economics'!D12 -> 0 | J22: =J15*'Unit Economics'!D12 -> 0 | K22: =K15*'Unit Economics'!D12 -> 0 | L22: =L15*'Unit Economics'!D12 -> 0 | M22: =M15*'Unit Economics'!D12 -> 0 | N22: =N15*'Unit Economics'!D12 -> 0 | O22: =O15*'Unit Economics'!D12 -> 199.66667 | P22: =P15*'Unit Economics'!D12 -> 394.34167 | Q22: =Q15*'Unit Economics'!D12 -> 584.14979 | R22: =R15*'Unit Economics'!D12 -> 769.21271 | S22: =S15*'Unit Economics'!D12 -> 949.64906 | T22: =T15*'Unit Economics'!D12 -> 1125.5745 | U22: =U15*'Unit Economics'!D12 -> 1297.1018 | V22: =V15*'Unit Economics'!D12 -> 1464.3409 | W22: =W15*'Unit Economics'!D12 -> 1627.3991 | X22: =X15*'Unit Economics'!D12 -> 1786.3808 | Y22: =Y15*'Unit Economics'!D12 -> 1941.3879 | Z22: =Z15*'Unit Economics'!D12 -> 2092.5199
A23: Resort MRR | C23: =C16*'Unit Economics'!E12 -> 0 | D23: =D16*'Unit Economics'!E12 -> 0 | E23: =E16*'Unit Economics'!E12 -> 0 | F23: =F16*'Unit Economics'!E12 -> 0 | G23: =G16*'Unit Economics'!E12 -> 0 | H23: =H16*'Unit Economics'!E12 -> 0 | I23: =I16*'Unit Economics'!E12 -> 0 | J23: =J16*'Unit Economics'!E12 -> 0 | K23: =K16*'Unit Economics'!E12 -> 0 | L23: =L16*'Unit Economics'!E12 -> 0 | M23: =M16*'Unit Economics'!E12 -> 0 | N23: =N16*'Unit Economics'!E12 -> 0 | O23: =O16*'Unit Economics'!E12 -> 0 | P23: =P16*'Unit Economics'!E12 -> 0 | Q23: =Q16*'Unit Economics'!E12 -> 0 | R23: =R16*'Unit Economics'!E12 -> 0 | S23: =S16*'Unit Economics'!E12 -> 0 | T23: =T16*'Unit Economics'!E12 -> 0 | U23: =U16*'Unit Economics'!E12 -> 0 | V23: =V16*'Unit Economics'!E12 -> 0 | W23: =W16*'Unit Economics'!E12 -> 0 | X23: =X16*'Unit Economics'!E12 -> 366.33333 | Y23: =Y16*'Unit Economics'!E12 -> 723.50833 | Z23: =Z16*'Unit Economics'!E12 -> 1071.754
A24: Group MRR | C24: =C17*'Unit Economics'!F12 -> 0 | D24: =D17*'Unit Economics'!F12 -> 0 | E24: =E17*'Unit Economics'!F12 -> 0 | F24: =F17*'Unit Economics'!F12 -> 0 | G24: =G17*'Unit Economics'!F12 -> 0 | H24: =H17*'Unit Economics'!F12 -> 0 | I24: =I17*'Unit Economics'!F12 -> 0 | J24: =J17*'Unit Economics'!F12 -> 0 | K24: =K17*'Unit Economics'!F12 -> 0 | L24: =L17*'Unit Economics'!F12 -> 0 | M24: =M17*'Unit Economics'!F12 -> 0 | N24: =N17*'Unit Economics'!F12 -> 0 | O24: =O17*'Unit Economics'!F12 -> 0 | P24: =P17*'Unit Economics'!F12 -> 0 | Q24: =Q17*'Unit Economics'!F12 -> 0 | R24: =R17*'Unit Economics'!F12 -> 925.81667 | S24: =S17*'Unit Economics'!F12 -> 1828.4879 | T24: =T17*'Unit Economics'!F12 -> 2708.5924 | U24: =U17*'Unit Economics'!F12 -> 2640.8776 | V24: =V17*'Unit Economics'!F12 -> 2574.8556 | W24: =W17*'Unit Economics'!F12 -> 2510.4842 | X24: =X17*'Unit Economics'!F12 -> 2447.7221 | Y24: =Y17*'Unit Economics'!F12 -> 2386.5291 | Z24: =Z17*'Unit Economics'!F12 -> 2326.8659
A25: Total MRR | C25: =SUM(C20:C23)+C24 -> 99.666667 | D25: =SUM(D20:D23)+D24 -> 196.84167 | E25: =SUM(E20:E23)+E24 -> 291.58729 | F25: =SUM(F20:F23)+F24 -> 549.96428 | G25: =SUM(G20:G23)+G24 -> 801.88184 | H25: =SUM(H20:H23)+H24 -> 1047.5015 | I25: =SUM(I20:I23)+I24 -> 1286.9806 | J25: =SUM(J20:J23)+J24 -> 1520.4727 | ... Z25: =SUM(Z20:Z23)+Z24 -> 10259.893
A26: Cost of service
A27: Boutique COGS | C27: =C13*'Unit Economics'!B23 -> 0 | D27: =D13*'Unit Economics'!B23 -> 0 | E27: =E13*'Unit Economics'!B23 -> 0 | F27: =F13*'Unit Economics'!B23 -> 13.106627 | G27: =G13*'Unit Economics'!B23 -> 25.885588 | H27: =H13*'Unit Economics'!B23 -> 38.345075 | I27: =I13*'Unit Economics'!B23 -> 50.493075 | J27: =J13*'Unit Economics'!B23 -> 62.337375 | K27: =K13*'Unit Economics'!B23 -> 73.885567 | L27: =L13*'Unit Economics'!B23 -> 85.145055 | M27: =M13*'Unit Economics'!B23 -> 96.123055 | N27: =N13*'Unit Economics'!B23 -> 106.82661 | O27: =O13*'Unit Economics'!B23 -> 117.26257 | P27: =P13*'Unit Economics'!B23 -> 127.43763 | Q27: =Q13*'Unit Economics'!B23 -> 137.35832 | R27: =R13*'Unit Economics'!B23 -> 147.03099 | S27: =S13*'Unit Economics'!B23 -> 156.46184 | T27: =T13*'Unit Economics'!B23 -> 165.65692 | U27: =U13*'Unit Economics'!B23 -> 174.62212 | V27: =V13*'Unit Economics'!B23 -> 183.3632 | W27: =W13*'Unit Economics'!B23 -> 191.88574 | X27: =X13*'Unit Economics'!B23 -> 200.19523 | Y27: =Y13*'Unit Economics'!B23 -> 208.29697 | Z27: =Z13*'Unit Economics'!B23 -> 216.19617
A28: Independent COGS | C28: =C14*'Unit Economics'!C23 -> 19.688789 | D28: =D14*'Unit Economics'!C23 -> 38.885359 | E28: =E14*'Unit Economics'!C23 -> 57.602014 | F28: =F14*'Unit Economics'!C23 -> 95.539543 | G28: =G14*'Unit Economics'!C23 -> 132.52863 | H28: =H14*'Unit Economics'!C23 -> 168.593 | I28: =I14*'Unit Economics'!C23 -> 203.75575 | J28: =J14*'Unit Economics'!C23 -> 238.03943 | K28: =K14*'Unit Economics'!C23 -> 271.46603 | L28: =L14*'Unit Economics'!C23 -> 323.74574 | M28: =M14*'Unit Economics'!C23 -> 374.71847 | N28: =N14*'Unit Economics'!C23 -> 424.41688 | O28: =O14*'Unit Economics'!C23 -> 453.18403 | P28: =P14*'Unit Economics'!C23 -> 481.23201 | Q28: =Q14*'Unit Economics'!C23 -> 508.57879 | R28: =R14*'Unit Economics'!C23 -> 535.2419 | S28: =S14*'Unit Economics'!C23 -> 561.23843 | T28: =T14*'Unit Economics'!C23 -> 586.58505 | U28: =U14*'Unit Economics'!C23 -> 611.298 | V28: =V14*'Unit Economics'!C23 -> 635.39313 | W28: =W14*'Unit Economics'!C23 -> 658.88588 | X28: =X14*'Unit Economics'!C23 -> 681.79131 | Y28: =Y14*'Unit Economics'!C23 -> 704.12411 | Z28: =Z14*'Unit Economics'!C23 -> 725.89858
A29: Midscale COGS | C29: =C15*'Unit Economics'!D23 -> 0 | D29: =D15*'Unit Economics'!D23 -> 0 | E29: =E15*'Unit Economics'!D23 -> 0 | F29: =F15*'Unit Economics'!D23 -> 0 | G29: =G15*'Unit Economics'!D23 -> 0 | H29: =H15*'Unit Economics'!D23 -> 0 | I29: =I15*'Unit Economics'!D23 -> 0 | J29: =J15*'Unit Economics'!D23 -> 0 | K29: =K15*'Unit Economics'!D23 -> 0 | L29: =L15*'Unit Economics'!D23 -> 0 | M29: =M15*'Unit Economics'!D23 -> 0 | N29: =N15*'Unit Economics'!D23 -> 0 | O29: =O15*'Unit Economics'!D23 -> 40.07828 | P29: =P15*'Unit Economics'!D23 -> 79.154603 | Q29: =Q15*'Unit Economics'!D23 -> 117.25402 | R29: =R15*'Unit Economics'!D23 -> 154.40095 | S29: =S15*'Unit Economics'!D23 -> 190.6192 | T29: =T15*'Unit Economics'!D23 -> 225.932 | U29: =U15*'Unit Economics'!D23 -> 260.36198 | V29: =V15*'Unit Economics'!D23 -> 293.93121 | W29: =W15*'Unit Economics'!D23 -> 326.66121 | X29: =X15*'Unit Economics'!D23 -> 358.57296 | Y29: =Y15*'Unit Economics'!D23 -> 389.68692 | Z29: =Z15*'Unit Economics'!D23 -> 420.02303
A30: Resort COGS | C30: =C16*'Unit Economics'!E23 -> 0 | D30: =D16*'Unit Economics'!E23 -> 0 | E30: =E16*'Unit Economics'!E23 -> 0 | F30: =F16*'Unit Economics'!E23 -> 0 | G30: =G16*'Unit Economics'!E23 -> 0 | H30: =H16*'Unit Economics'!E23 -> 0 | I30: =I16*'Unit Economics'!E23 -> 0 | J30: =J16*'Unit Economics'!E23 -> 0 | K30: =K16*'Unit Economics'!E23 -> 0 | L30: =L16*'Unit Economics'!E23 -> 0 | M30: =M16*'Unit Economics'!E23 -> 0 | N30: =N16*'Unit Economics'!E23 -> 0 | O30: =O16*'Unit Economics'!E23 -> 0 | P30: =P16*'Unit Economics'!E23 -> 0 | Q30: =Q16*'Unit Economics'!E23 -> 0 | R30: =R16*'Unit Economics'!E23 -> 0 | S30: =S16*'Unit Economics'!E23 -> 0 | T30: =T16*'Unit Economics'!E23 -> 0 | U30: =U16*'Unit Economics'!E23 -> 0 | V30: =V16*'Unit Economics'!E23 -> 0 | W30: =W16*'Unit Economics'!E23 -> 0 | X30: =X16*'Unit Economics'!E23 -> 78.981467 | Y30: =Y16*'Unit Economics'!E23 -> 155.9884 | Z30: =Z16*'Unit Economics'!E23 -> 231.07015
A31: Group COGS | C31: =C17*'Unit Economics'!F23 -> 0 | D31: =D17*'Unit Economics'!F23 -> 0 | E31: =E17*'Unit Economics'!F23 -> 0 | F31: =F17*'Unit Economics'!F23 -> 0 | G31: =G17*'Unit Economics'!F23 -> 0 | H31: =H17*'Unit Economics'!F23 -> 0 | I31: =I17*'Unit Economics'!F23 -> 0 | J31: =J17*'Unit Economics'!F23 -> 0 | K31: =K17*'Unit Economics'!F23 -> 0 | L31: =L17*'Unit Economics'!F23 -> 0 | M31: =M17*'Unit Economics'!F23 -> 0 | N31: =N17*'Unit Economics'!F23 -> 0 | O31: =O17*'Unit Economics'!F23 -> 0 | P31: =P17*'Unit Economics'!F23 -> 0 | Q31: =Q17*'Unit Economics'!F23 -> 0 | R31: =R17*'Unit Economics'!F23 -> 136.29387 | S31: =S17*'Unit Economics'!F23 -> 269.18039 | T31: =T17*'Unit Economics'!F23 -> 398.74474 | U31: =U17*'Unit Economics'!F23 -> 388.77613 | V31: =V17*'Unit Economics'!F23 -> 379.05672 | W31: =W17*'Unit Economics'!F23 -> 369.5803 | X31: =X17*'Unit Economics'!F23 -> 360.3408 | Y31: =Y17*'Unit Economics'!F23 -> 351.33228 | Z31: =Z17*'Unit Economics'!F23 -> 342.54897
A32: Total COGS | C32: =SUM(C27:C30)+C31 -> 19.688789 | D32: =SUM(D27:D30)+D31 -> 38.885359 | E32: =SUM(E27:E30)+E31 -> 57.602014 | F32: =SUM(F27:F30)+F31 -> 108.64617 | G32: =SUM(G27:G30)+G31 -> 158.41422 | H32: =SUM(H27:H30)+H31 -> 206.93807 | I32: =SUM(I27:I30)+I31 -> 254.24882 | J32: =SUM(J27:J30)+J31 -> 300.37681 | ... Z32: =SUM(Z27:Z30)+Z31 -> 1935.7369
A33: Gross profit | C33: =C25-C32 -> 79.977877 | D33: =D25-D32 -> 157.95631 | E33: =E25-E32 -> 233.98528 | F33: =F25-F32 -> 441.31811 | G33: =G25-G32 -> 643.46762 | H33: =H25-H32 -> 840.56339 | I33: =I25-I32 -> 1032.7318 | J33: =J25-J32 -> 1220.0959 | ... Z33: =Z25-Z32 -> 8324.156
A34: Gross margin % | C34: =IF(C25=0,0,C33/C25) -> 0.80245362 | D34: =IF(D25=0,0,D33/D25) -> 0.80245362 | E34: =IF(E25=0,0,E33/E25) -> 0.80245362 | F34: =IF(F25=0,0,F33/F25) -> 0.80244868 | G34: =IF(G25=0,0,G33/G25) -> 0.80244693 | H34: =IF(H25=0,0,H33/H25) -> 0.80244603 | I34: =IF(I25=0,0,I33/I25) -> 0.80244549 | J34: =IF(J25=0,0,J33/J25) -> 0.80244512 | ... Z34: =IF(Z25=0,0,Z33/Z25) -> 0.81132972
A35: Operating costs
A36: Founder 1 | C36: =Inputs!$B$61 -> 2500 | D36: =Inputs!$B$61 -> 2500 | E36: =Inputs!$B$61 -> 2500 | F36: =Inputs!$B$61 -> 2500 | G36: =Inputs!$B$61 -> 2500 | H36: =Inputs!$B$61 -> 2500 | I36: =Inputs!$B$61 -> 2500 | J36: =Inputs!$B$61 -> 2500 | ... Z36: =Inputs!$B$61 -> 2500
A37: Founder 2 | C37: =Inputs!$B$62 -> 0 | D37: =Inputs!$B$62 -> 0 | E37: =Inputs!$B$62 -> 0 | F37: =Inputs!$B$62 -> 0 | G37: =Inputs!$B$62 -> 0 | H37: =Inputs!$B$62 -> 0 | I37: =Inputs!$B$62 -> 0 | J37: =Inputs!$B$62 -> 0 | ... Z37: =Inputs!$B$62 -> 0
A38: Developer | C38: =Inputs!$B$63 -> 3500 | D38: =Inputs!$B$63 -> 3500 | E38: =Inputs!$B$63 -> 3500 | F38: =Inputs!$B$63 -> 3500 | G38: =Inputs!$B$63 -> 3500 | H38: =Inputs!$B$63 -> 3500 | I38: =Inputs!$B$63 -> 3500 | J38: =Inputs!$B$63 -> 3500 | ... Z38: =Inputs!$B$63 -> 3500
A39: Second developer | C39: =IF(1>=Inputs!$B$64,Inputs!$B$65,0) -> 0 | D39: =IF(2>=Inputs!$B$64,Inputs!$B$65,0) -> 0 | E39: =IF(3>=Inputs!$B$64,Inputs!$B$65,0) -> 0 | F39: =IF(4>=Inputs!$B$64,Inputs!$B$65,0) -> 0 | G39: =IF(5>=Inputs!$B$64,Inputs!$B$65,0) -> 0 | H39: =IF(6>=Inputs!$B$64,Inputs!$B$65,0) -> 0 | I39: =IF(7>=Inputs!$B$64,Inputs!$B$65,0) -> 3500 | J39: =IF(8>=Inputs!$B$64,Inputs!$B$65,0) -> 3500 | K39: =IF(9>=Inputs!$B$64,Inputs!$B$65,0) -> 3500 | L39: =IF(10>=Inputs!$B$64,Inputs!$B$65,0) -> 3500 | M39: =IF(11>=Inputs!$B$64,Inputs!$B$65,0) -> 3500 | N39: =IF(12>=Inputs!$B$64,Inputs!$B$65,0) -> 3500 | O39: =IF(13>=Inputs!$B$64,Inputs!$B$65,0) -> 3500 | P39: =IF(14>=Inputs!$B$64,Inputs!$B$65,0) -> 3500 | Q39: =IF(15>=Inputs!$B$64,Inputs!$B$65,0) -> 3500 | R39: =IF(16>=Inputs!$B$64,Inputs!$B$65,0) -> 3500 | S39: =IF(17>=Inputs!$B$64,Inputs!$B$65,0) -> 3500 | T39: =IF(18>=Inputs!$B$64,Inputs!$B$65,0) -> 3500 | U39: =IF(19>=Inputs!$B$64,Inputs!$B$65,0) -> 3500 | V39: =IF(20>=Inputs!$B$64,Inputs!$B$65,0) -> 3500 | W39: =IF(21>=Inputs!$B$64,Inputs!$B$65,0) -> 3500 | X39: =IF(22>=Inputs!$B$64,Inputs!$B$65,0) -> 3500 | Y39: =IF(23>=Inputs!$B$64,Inputs!$B$65,0) -> 3500 | Z39: =IF(24>=Inputs!$B$64,Inputs!$B$65,0) -> 3500
A40: Support / content ops | C40: =IF(1>=Inputs!$B$66,Inputs!$B$67,0) -> 0 | D40: =IF(2>=Inputs!$B$66,Inputs!$B$67,0) -> 0 | E40: =IF(3>=Inputs!$B$66,Inputs!$B$67,0) -> 0 | F40: =IF(4>=Inputs!$B$66,Inputs!$B$67,0) -> 1300 | G40: =IF(5>=Inputs!$B$66,Inputs!$B$67,0) -> 1300 | H40: =IF(6>=Inputs!$B$66,Inputs!$B$67,0) -> 1300 | I40: =IF(7>=Inputs!$B$66,Inputs!$B$67,0) -> 1300 | J40: =IF(8>=Inputs!$B$66,Inputs!$B$67,0) -> 1300 | K40: =IF(9>=Inputs!$B$66,Inputs!$B$67,0) -> 1300 | L40: =IF(10>=Inputs!$B$66,Inputs!$B$67,0) -> 1300 | M40: =IF(11>=Inputs!$B$66,Inputs!$B$67,0) -> 1300 | N40: =IF(12>=Inputs!$B$66,Inputs!$B$67,0) -> 1300 | O40: =IF(13>=Inputs!$B$66,Inputs!$B$67,0) -> 1300 | P40: =IF(14>=Inputs!$B$66,Inputs!$B$67,0) -> 1300 | Q40: =IF(15>=Inputs!$B$66,Inputs!$B$67,0) -> 1300 | R40: =IF(16>=Inputs!$B$66,Inputs!$B$67,0) -> 1300 | S40: =IF(17>=Inputs!$B$66,Inputs!$B$67,0) -> 1300 | T40: =IF(18>=Inputs!$B$66,Inputs!$B$67,0) -> 1300 | U40: =IF(19>=Inputs!$B$66,Inputs!$B$67,0) -> 1300 | V40: =IF(20>=Inputs!$B$66,Inputs!$B$67,0) -> 1300 | W40: =IF(21>=Inputs!$B$66,Inputs!$B$67,0) -> 1300 | X40: =IF(22>=Inputs!$B$66,Inputs!$B$67,0) -> 1300 | Y40: =IF(23>=Inputs!$B$66,Inputs!$B$67,0) -> 1300 | Z40: =IF(24>=Inputs!$B$66,Inputs!$B$67,0) -> 1300
A41: Tools | C41: =Inputs!$B$68 -> 400 | D41: =Inputs!$B$68 -> 400 | E41: =Inputs!$B$68 -> 400 | F41: =Inputs!$B$68 -> 400 | G41: =Inputs!$B$68 -> 400 | H41: =Inputs!$B$68 -> 400 | I41: =Inputs!$B$68 -> 400 | J41: =Inputs!$B$68 -> 400 | ... Z41: =Inputs!$B$68 -> 400
...

Sheet Scenarios
A1: Three funding paths compared
A2: Static snapshot computed from the same engine. Switch the selector on Inputs to reproduce any column live.
A4: Metric | B4: Bootstrap | C4: Funded | D4: Group-led
A5: Team shape | B5: Bootstrap: 2 founders, both build; no contractor, founders absorb support. | Funded: 1 founder + contractor dev, then a second dev (month 7) and support ops (month 4). | Group-led: same team as Funded, faster pipeline, two group deals.
A7: Steady-state monthly opex | B7: 3800 | C7: 12000 | D7: 12400
A8: Properties at month 24 | B8: 15.579549 | C8: 22.256499 | D8: 31.159098
A9: Group deals at month 24 | B9: 0 | C9: 0.83777057 | D9: 1.5709437
A10: MRR at month 24 | B10: 5553.1189 | C10: 10259.893 | D10: 15469.455
A11: ARR at month 24 | B11: 66637.427 | C11: 123118.71 | D11: 185633.46
A12: Gross margin at month 24 | B12: 0.79917024 | C12: 0.81132985 | D12: 0.81429271
A13: EBITDA at month 24 | B13: 637.88738 | C13: -3675.8427 | D13: 196.66479
A14: Breakeven month | B14: 23 | C14: not within 24 months | D14: 24
A15: Peak funding requirement | B15: 50926.415 | C15: 230511.73 | D15: 188452.34
A16: Cash at month 24 | B16: 9989.2174 | C16: -80511.729 | D16: -38255.676
A17: Starting capital raise | B17: 60000 | C17: 150000 | D17: 150000
A19: Reading the three paths
A20: Bootstrap | B20: Lowest capital consumed (~$51k peak) and the only path that reaches breakeven on a plausible timeline — month 23, with $10k of cash left at month 24. It works only if both founders take a $1,500/month draw. That is a runway decision, not a business decision.
A21: Funded | B21: The middle path is the worst path. It needs ~$231k of peak funding and still does not reach breakeven within 24 months at base-case sales velocity — $80k short at month 24. You take venture-scale burn without venture-scale growth.
A22: Group-led | B22: Breakeven month 24 at ~$188k consumed. Group revenue per deal is ~9× an independent property, so the same sales effort buys far more gross profit. Two group logos beat forty independents on capital efficiency.
A23: The decision this forces | B23: Either bootstrap with two founders and accept a slow 23-month climb, or raise ~$200k deliberately and staff for the group path. Do not drift into the middle by hiring one contractor and hoping.

Sheet Sensitivity
A1: What actually moves the answer
A3: A. Gross margin — Independent tier (rows: conversation volume vs base; columns: WhatsApp share)
A4: Volume multiple | B4: 0% | C4: 25% | D4: 45% | E4: 65% | F4: 85%
A5: 0.5× | B5: 0.81132045 | C5: 0.81132045 | D5: 0.81132045 | E5: 0.81132045 | F5: 0.81132045
A6: 1.0× | B6: 0.80245362 | C6: 0.80245362 | D6: 0.80245362 | E6: 0.80223302 | F6: 0.79341803
A7: 1.5× | B7: 0.79358678 | C7: 0.79358678 | D7: 0.79226431 | E7: 0.77904183 | F7: 0.76581936
A8: 2.0× | B8: 0.78471995 | C8: 0.78471995 | D8: 0.77348062 | E8: 0.75585065 | F8: 0.73822068
A9: 3.0× | B9: 0.76698627 | C9: 0.76235818 | D9: 0.73591323 | E9: 0.70946828 | F9: 0.68302333
A11: Conclusion: margin never falls below 72% anywhere in the plausible range. Do not spend engineering effort optimising AI cost.
A13: B. Support load is the real lever — Independent tier
A14: Support hrs / month | B14: Support cost | C14: COGS | D14: GM % | E14: GP / month | F14: Properties per $10k opex
A15: 0.5 | B15: 11 | C15: 37.066368 | D15: 0.87603221 | E15: 261.93363 | F15: 38.17761
A16: 1.0 | B16: 22 | C16: 48.066368 | D16: 0.83924292 | E16: 250.93363 | F16: 39.851175
A17: 1.5 | B17: 33 | C17: 59.066368 | D17: 0.80245362 | E17: 239.93363 | F17: 41.678192
A18: 2.0 | B18: 44 | C18: 70.066368 | D18: 0.76566432 | E18: 228.93363 | F18: 43.680782
A19: 3.0 | B19: 66 | C19: 92.066368 | D19: 0.69208573 | E19: 206.93363 | F19: 48.324673
A20: 4.0 | B20: 88 | C20: 114.06637 | D20: 0.61850713 | E20: 184.93363 | F20: 54.073453
A22: Every extra support hour per property per month costs ~$22 and delays breakeven materially. Self-serve onboarding and a good knowledge-gap loop are margin features, not niceties.
A24: C. LLM model tier — cost per conversation
A25: Model tier | B25: $/conv | C25: COGS (Independent) | D25: GM % | E25: COGS (Resort) | F25: GM % (Resort) | G25: Verdict
A26: Cheap (Flash/mini class) | B26: 0.00855 | C26: 55.089592 | D26: 0.81575387 | E26: 210.6275 | F26: 0.80834622 | G26: Use for classification and guardrail passes
A27: Mid (default) | B27: 0.0342 | C27: 59.066368 | D27: 0.80245362 | E27: 236.9444 | F27: 0.7844 | G27: Recommended for generation
A28: Premium (frontier) | B28: 0.18 | C28: 81.6712 | D28: 0.72685217 | E28: 386.5352 | F28: 0.64828462 | G28: Only if mid-tier accuracy fails the eval gate
A30: D. The assumption that matters most
A31: • Participation rate — the share of guest-nights that produce a conversation. Modelled at 12–18%. If it is 5%, the product is a curiosity. If it is 30%, volumes (and WhatsApp cost) double, and margin still holds at ~77%.
A32: • Support hours per property — modelled at 1.5/month for an Independent. This is the number to measure during the pilot. Everything else in the model is more predictable than this.
A33: • Churn — 2.5%/month is an assumption, not evidence. A hotel that stops maintaining its knowledge base will churn. This is why the knowledge-gap loop is a retention feature.

Sheet Buyer ROI
A1: Buyer-side ROI — what the hotel gets for the price
A2: The seller's margin is fine everywhere. The buyer's case is not. This sheet tests whether a hotel can justify the price.
A4: A. Where the AI creates value for the hotel (edit yellow cells)
A5: Front-desk loaded hourly cost (USD) | B5: 6 | C5: Mexico ≈ $5–7/hr fully loaded. US resort ≈ $18–22/hr. Hotel labour rates are highly location-dependent.
A6: Staff minutes per conversation handled manually | B6: 8 | C6: Reading, thinking, replying, following up. 10-message WhatsApp threads take 8–12 minutes.
A7: Containment rate (AI resolves without staff) | B7: 0.55 | C7: Pilot target. Everything below assumes you hit it.
A8: After-hours share of conversations | B8: 0.35 | C8: Guests message at night. Today those go unanswered until morning.
A9: Staff minutes per after-hours conversation | B9: 15 | C9: Slower because nobody is at a desk.
A10: Opportunity clicks per conversation | B10: 0.08 | C10: Booking / dining / spa links. Conservative.
A11: Click-to-booking conversion | B11: 0.15 | C11: Unvalidated. Use 0 once you have real data.
A12: Average ancillary ticket (USD) | B12: 60
A13: Margin on that ticket | B13: 0.35
A16: B. Value created vs price charged
A17: Line | B17: Boutique | C17: Independent | D17: Midscale | E17: Resort | F17: Group (3×Mid) | G17: Note
A18: Conversations / month | B18: ='Unit Economics'!B16 -> 63.03744 | C18: ='Unit Economics'!C16 -> 155.04 | D18: ='Unit Economics'!D16 -> 434.112 | E18: ='Unit Economics'!E16 -> 1026 | F18: ='Unit Economics'!F16 -> 1149.12
A19: Conversations resolved without staff | B19: ='Unit Economics'!B16*$B$7 -> 34.670592 | C19: ='Unit Economics'!C16*$B$7 -> 85.272 | D19: ='Unit Economics'!D16*$B$7 -> 238.7616 | E19: ='Unit Economics'!E16*$B$7 -> 564.3 | F19: ='Unit Economics'!F16*$B$7 -> 632.016
A20: Staff time freed / month (hours) | B20: ='Unit Economics'!B16*$B$7*$B$6/60 -> 4.6227456 | C20: ='Unit Economics'!C16*$B$7*$B$6/60 -> 11.3696 | D20: ='Unit Economics'!D16*$B$7*$B$6/60 -> 31.83488 | E20: ='Unit Economics'!E16*$B$7*$B$6/60 -> 75.24 | F20: ='Unit Economics'!F16*$B$7*$B$6/60 -> 84.2688
A21: Value: staff time freed | B21: =B20*$B$5 -> 27.736474 | C21: =C20*$B$5 -> 68.2176 | D21: =D20*$B$5 -> 191.00928 | E21: =E20*$B$5 -> 451.44 | F21: =F20*$B$5 -> 505.6128 | G21: Replaces existing work
A22: Value: after-hours coverage | B22: =B18*$B$8*$B$9/60*$B$5 -> 33.094656 | C22: =C18*$B$8*$B$9/60*$B$5 -> 81.396 | D22: =D18*$B$8*$B$9/60*$B$5 -> 227.9088 | E22: =E18*$B$8*$B$9/60*$B$5 -> 538.65 | F22: =F18*$B$8*$B$9/60*$B$5 -> 603.288 | G22: Work that currently is not done at all
A23: Value: opportunity clicks | B23: =B18*$B$10*$B$11*$B$12*$B$13 -> 15.885435 | C23: =C18*$B$10*$B$11*$B$12*$B$13 -> 39.07008 | D23: =D18*$B$10*$B$11*$B$12*$B$13 -> 109.39622 | E23: =E18*$B$10*$B$11*$B$12*$B$13 -> 258.552 | F23: =F18*$B$10*$B$11*$B$12*$B$13 -> 289.57824 | G23: Weakest of the three — treat as upside only
A24: Total hard value / month | B24: =SUM(B21:B23) -> 76.716564 | C24: =SUM(C21:C23) -> 188.68368 | D24: =SUM(D21:D23) -> 528.3143 | E24: =SUM(E21:E23) -> 1248.642 | F24: =SUM(F21:F23) -> 1398.479
A25: Price / month | B25: ='Unit Economics'!B12 -> 199 | C25: ='Unit Economics'!C12 -> 299 | D25: ='Unit Economics'!D12 -> 599 | E25: ='Unit Economics'!E12 -> 1099 | F25: ='Unit Economics'!F12 -> 2777.45
A26: ROI multiple (value ÷ price) | B26: =B24/B25 -> 0.38551037 | C26: =C24/C25 -> 0.6310491 | D26: =D24/D25 -> 0.88199383 | E26: =E24/E25 -> 1.136162 | F26: =F24/F25 -> 0.50351187
A27: Net monthly value to the hotel | B27: =B24-B25 -> -122.28344 | C27: =C24-C25 -> -110.31632 | D27: =D24-D25 -> -70.685696 | E27: =E24-E25 -> 149.642 | F27: =F24-F25 -> -1378.971
A28: Group ROI is not comparable: groups buy governance, brand consistency and oversight, not hours saved. Judge that tier on seller margin (85%) and retention, not this ratio.
A29: C. Participation rate needed for the buyer to break even on hard value alone
A30: Price / mo | B30: Boutique | C30: Independent | D30: Midscale | E30: Resort | G30: Reading
A31: 199 | B31: =A31/($B$7*$B$6/60*$B$5+$B$8*$B$9/60*$B$5+$B$10*$B$11*$B$12*$B$13)/'Unit Economics'!B15 -> 0.31127567 | C31: =A31/($B$7*$B$6/60*$B$5+$B$8*$B$9/60*$B$5+$B$10*$B$11*$B$12*$B$13)/'Unit Economics'!C15 -> 0.15820128 | D31: =A31/($B$7*$B$6/60*$B$5+$B$8*$B$9/60*$B$5+$B$10*$B$11*$B$12*$B$13)/'Unit Economics'!D15 -> 0.064033852 | E31: =A31/($B$7*$B$6/60*$B$5+$B$8*$B$9/60*$B$5+$B$10*$B$11*$B$12*$B$13)/'Unit Economics'!E15 -> 0.028687166
A32: 299 | B32: =A32/($B$7*$B$6/60*$B$5+$B$8*$B$9/60*$B$5+$B$10*$B$11*$B$12*$B$13)/'Unit Economics'!B15 -> 0.4676956 | C32: =A32/($B$7*$B$6/60*$B$5+$B$8*$B$9/60*$B$5+$B$10*$B$11*$B$12*$B$13)/'Unit Economics'!C15 -> 0.23769941 | D32: =A32/($B$7*$B$6/60*$B$5+$B$8*$B$9/60*$B$5+$B$10*$B$11*$B$12*$B$13)/'Unit Economics'!D15 -> 0.096211667 | E32: =A32/($B$7*$B$6/60*$B$5+$B$8*$B$9/60*$B$5+$B$10*$B$11*$B$12*$B$13)/'Unit Economics'!E15 -> 0.043102827
A33: 349 | B33: =A33/($B$7*$B$6/60*$B$5+$B$8*$B$9/60*$B$5+$B$10*$B$11*$B$12*$B$13)/'Unit Economics'!B15 -> 0.54590557 | C33: =A33/($B$7*$B$6/60*$B$5+$B$8*$B$9/60*$B$5+$B$10*$B$11*$B$12*$B$13)/'Unit Economics'!C15 -> 0.27744848 | D33: =A33/($B$7*$B$6/60*$B$5+$B$8*$B$9/60*$B$5+$B$10*$B$11*$B$12*$B$13)/'Unit Economics'!D15 -> 0.11230057 | E33: =A33/($B$7*$B$6/60*$B$5+$B$8*$B$9/60*$B$5+$B$10*$B$11*$B$12*$B$13)/'Unit Economics'!E15 -> 0.050310657
A34: 599 | B34: =A34/($B$7*$B$6/60*$B$5+$B$8*$B$9/60*$B$5+$B$10*$B$11*$B$12*$B$13)/'Unit Economics'!B15 -> 0.93695541 | C34: =A34/($B$7*$B$6/60*$B$5+$B$8*$B$9/60*$B$5+$B$10*$B$11*$B$12*$B$13)/'Unit Economics'!C15 -> 0.47619381 | D34: =A34/($B$7*$B$6/60*$B$5+$B$8*$B$9/60*$B$5+$B$10*$B$11*$B$12*$B$13)/'Unit Economics'!D15 -> 0.19274511 | E34: =A34/($B$7*$B$6/60*$B$5+$B$8*$B$9/60*$B$5+$B$10*$B$11*$B$12*$B$13)/'Unit Economics'!E15 -> 0.08634981
A35: 1099 | B35: =A35/($B$7*$B$6/60*$B$5+$B$8*$B$9/60*$B$5+$B$10*$B$11*$B$12*$B$13)/'Unit Economics'!B15 -> 1.7190551 | C35: =A35/($B$7*$B$6/60*$B$5+$B$8*$B$9/60*$B$5+$B$10*$B$11*$B$12*$B$13)/'Unit Economics'!C15 -> 0.87368446 | D35: =A35/($B$7*$B$6/60*$B$5+$B$8*$B$9/60*$B$5+$B$10*$B$11*$B$12*$B$13)/'Unit Economics'!D15 -> 0.35363419 | E35: =A35/($B$7*$B$6/60*$B$5+$B$8*$B$9/60*$B$5+$B$10*$B$11*$B$12*$B$13)/'Unit Economics'!E15 -> 0.15842812
A36: Base participation modelled: 12% Boutique, 15% Independent, 17% Midscale, 18% Resort. If the required rate is above the base, labour value alone does not pay for the product at that price — the buyer must value coverage, reviews or revenue.
A38: D. The same product at two labour markets
A39: Labour market | B39: Boutique | C39: Independent | D39: Midscale | E39: Resort
A40: Mexico ($6.00/hr) | B40: ='Unit Economics'!B16*1.2169999999999999/'Unit Economics'!B12 -> 0.38551037 | C40: ='Unit Economics'!C16*1.2169999999999999/'Unit Economics'!C12 -> 0.6310491 | D40: ='Unit Economics'!D16*1.2169999999999999/'Unit Economics'!D12 -> 0.88199383 | E40: ='Unit Economics'!E16*1.2169999999999999/'Unit Economics'!E12 -> 1.136162
A41: US / high-wage resort ($19.00/hr) | B41: ='Unit Economics'!B16*3.307833333333333/'Unit Economics'!B12 -> 1.0478259 | C41: ='Unit Economics'!C16*3.307833333333333/'Unit Economics'!C12 -> 1.7152056 | D41: ='Unit Economics'!D16*3.307833333333333/'Unit Economics'!D12 -> 2.397279 | E41: ='Unit Economics'!E16*3.307833333333333/'Unit Economics'!E12 -> 3.0881137
A43: E. What this means for pricing
A44: The seller's economics are not the problem | B44: Gross margin is 78–85% at every tier. There is no cost crisis to solve.
A45: The buyer's case is location-dependent | B45: At Mexican labour rates ($6/hr) buyer ROI is 0.39× (Boutique) to 1.14× (Resort) on hard value. At US resort rates ($19/hr) it is 1.05× to 3.09×. Same product, different verdict.
...

Sheet Sources & method
A1: Sources, method and open questions
A3: WhatsApp pricing | B3: Service messages became chargeable on 1 Oct 2026. 1,000 free service messages per business phone number per month, then billed at the market utility rate. Mexico ≈ $0.0085/message.
A4: Source | B4: Meta, Pricing on the WhatsApp Business Platform — developers.facebook.com/documentation/business-messaging/whatsapp/pricing
A5: Data protection | B5: LFPDPPP (Mexico) effective 21 Mar 2025. Processors directly regulated; INAI dissolved, enforcement moved to the Secretaría Anticorrupción y Buen Gobierno. Implications: DPA required, purposes enumerated, no 'similar purposes' catch-all.
A6: Build cost basis | B6: 77 dev-days from the delivery backlog (70 items, 68 of them on the lean pilot path) at $550/day, plus design, legal and 2 months of managed services. The backlog is the single source of truth for schedule arithmetic. See 02-development-plan-workbook.xlsx, sheet 02.
A7: Participation rate | B7: No public benchmark exists for AI concierge adoption in Mexico. 12–18% of guest-nights is an assumption to be replaced with pilot data in weeks 1–4.
A8: Support load | B8: 1.5 hours per Independent property per month assumes a maintained knowledge base and a self-serve onboarding. Add 0.5–1.0 h/month for the first 90 days of each property.
A9: Churn | B9: 2.5%/month (26% annualised) is a standard SMB SaaS placeholder. Hotel software typically churns less once embedded; this product is not yet embedded.
A10: Currency & tax | B10: USD. Mexican IVA (16%) and local card processing should be layered on before quoting. The model uses a 3.6% payment fee before tax.
A11: Known simplification: group churn | B11: Groups are churned at the same 2.5%/month as single properties. In reality group churn is probably lower and lumpier. This makes the group-led scenario slightly conservative.
A12: Known simplification: billing cadence | B12: All pricing is modelled monthly. Annual prepay (recommended in the Pricing sheet) improves cash timing but does not change ARR, so it is not modelled separately.
A13: Bootstrap build cost | B13: $2,280 = legal and incorporation $1,800 + two months of managed services $240 + $240 domain and tooling. Founders contribute the development.
A14: Cached values | B14: Every formula cell also stores its computed value, so the workbook reads correctly in pandas, Sheets, previewers and any tool that does not recalculate. Rebuild with build_finmodel.py then bake_values.py.
A16: Open questions this model cannot answer
A17: 1 | B17: What participation rate will guests actually show? Only the pilot can answer this, and it changes everything downstream.
A18: 2 | B18: Will a hotel pay $349/month for a product their staff must maintain? The knowledge-gap loop is the mechanism; the pilot tests it.
A19: 3 | B19: Can a group be sold without PMS integration? The model assumes yes at $1,250 platform + 85% per property. That is unvalidated.
A20: 4 | B20: What is real support load in month 3, after the hotel edits its own knowledge badly? Model 2.5 h/month in that period.
